<?xml version="1.0"?>
<robot name="complete_humanoid">
  <!-- This is a complete humanoid robot model with all major body parts -->

  <!-- Base/Fixed frame -->
  <link name="base_link">
    <inertial>
      <mass value="0.0001"/>
      <inertia ixx="0.0001" ixy="0" ixz="0" iyy="0.0001" iyz="0" izz="0.0001"/>
    </inertial>
  </link>

  <!-- Pelvis -->
  <link name="pelvis">
    <visual>
      <origin xyz="0 0 0" rpy="0 0 0"/>
      <geometry>
        <box size="0.25 0.2 0.15"/>
      </geometry>
      <material name="light_gray">
        <color rgba="0.7 0.7 0.7 1.0"/>
      </material>
    </visual>
    <collision>
      <origin xyz="0 0 0" rpy="0 0 0"/>
      <geometry>
        <box size="0.25 0.2 0.15"/>
      </geometry>
    </collision>
    <inertial>
      <mass value="5.0"/>
      <origin xyz="0 0 0" rpy="0 0 0"/>
      <inertia ixx="0.05" ixy="0" ixz="0" iyy="0.06" iyz="0" izz="0.04"/>
    </inertial>
  </link>

  <joint name="base_to_pelvis" type="fixed">
    <parent link="base_link"/>
    <child link="pelvis"/>
    <origin xyz="0 0 0"/>
  </joint>

  <!-- Torso/Spine -->
  <link name="torso">
    <visual>
      <origin xyz="0 0 0.25" rpy="0 0 0"/>
      <geometry>
        <box size="0.25 0.15 0.5"/>
      </geometry>
      <material name="light_gray">
        <color rgba="0.7 0.7 0.7 1.0"/>
      </material>
    </visual>
    <collision>
      <origin xyz="0 0 0.25" rpy="0 0 0"/>
      <geometry>
        <box size="0.25 0.15 0.5"/>
      </geometry>
    </collision>
    <inertial>
      <mass value="10.0"/>
      <origin xyz="0 0 0.25" rpy="0 0 0"/>
      <inertia ixx="0.3" ixy="0" ixz="0" iyy="0.4" iyz="0" izz="0.25"/>
    </inertial>
  </link>

  <joint name="torso_joint" type="revolute">
    <parent link="pelvis"/>
    <child link="torso"/>
    <origin xyz="0 0 0.075"/>
    <axis xyz="0 0 1"/>
    <limit lower="-0.5" upper="0.5" effort="20.0" velocity="1.0"/>
    <dynamics damping="1.0" friction="0.1"/>
  </joint>

  <!-- Head -->
  <link name="neck">
    <visual>
      <origin xyz="0 0 0.075" rpy="0 0 0"/>
      <geometry>
        <cylinder radius="0.05" length="0.15"/>
      </geometry>
      <material name="skin">
        <color rgba="1.0 0.8 0.6 1.0"/>
      </material>
    </visual>
    <collision>
      <origin xyz="0 0 0.075" rpy="0 0 0"/>
      <geometry>
        <cylinder radius="0.05" length="0.15"/>
      </geometry>
    </collision>
    <inertial>
      <mass value="1.0"/>
      <origin xyz="0 0 0.075" rpy="0 0 0"/>
      <inertia ixx="0.002" ixy="0" ixz="0" iyy="0.002" iyz="0" izz="0.001"/>
    </inertial>
  </link>

  <joint name="neck_joint" type="revolute">
    <parent link="torso"/>
    <child link="neck"/>
    <origin xyz="0 0 0.5"/>
    <axis xyz="0 1 0"/>
    <limit lower="-0.5" upper="0.5" effort="5.0" velocity="2.0"/>
    <dynamics damping="0.5" friction="0.1"/>
  </joint>

  <link name="head">
    <visual>
      <origin xyz="0 0 0.1" rpy="0 0 0"/>
      <geometry>
        <sphere radius="0.12"/>
      </geometry>
      <material name="skin">
        <color rgba="1.0 0.8 0.6 1.0"/>
      </material>
    </visual>
    <collision>
      <origin xyz="0 0 0.1" rpy="0 0 0"/>
      <geometry>
        <sphere radius="0.12"/>
      </geometry>
    </collision>
    <inertial>
      <mass value="3.0"/>
      <origin xyz="0 0 0.1" rpy="0 0 0"/>
      <inertia ixx="0.02" ixy="0" ixz="0" iyy="0.02" iyz="0" izz="0.02"/>
    </inertial>
  </link>

  <joint name="head_joint" type="revolute">
    <parent link="neck"/>
    <child link="head"/>
    <origin xyz="0 0 0.15"/>
    <axis xyz="0 1 0"/>
    <limit lower="-0.5" upper="0.5" effort="5.0" velocity="2.0"/>
    <dynamics damping="0.5" friction="0.1"/>
  </joint>

  <!-- Left Arm -->
  <link name="left_shoulder">
    <visual>
      <origin xyz="0.0 0 0" rpy="0 0 0"/>
      <geometry>
        <cylinder radius="0.06" length="0.12"/>
      </geometry>
      <material name="light_gray">
        <color rgba="0.7 0.7 0.7 1.0"/>
      </material>
    </visual>
    <collision>
      <origin xyz="0.0 0 0" rpy="0 0 0"/>
      <geometry>
        <cylinder radius="0.06" length="0.12"/>
      </geometry>
    </collision>
    <inertial>
      <mass value="1.0"/>
      <origin xyz="0 0 0" rpy="0 0 0"/>
      <inertia ixx="0.001" ixy="0" ixz="0" iyy="0.001" iyz="0" izz="0.002"/>
    </inertial>
  </link>

  <joint name="left_shoulder_yaw" type="revolute">
    <parent link="torso"/>
    <child link="left_shoulder"/>
    <origin xyz="0.125 0.05 0.25"/>
    <axis xyz="0 0 1"/>
    <limit lower="-1.57" upper="0.5" effort="10.0" velocity="2.0"/>
    <dynamics damping="1.0" friction="0.1"/>
  </joint>

  <link name="left_upper_arm">
    <visual>
      <origin xyz="0 0 -0.15" rpy="1.57079632679 0 0"/>
      <geometry>
        <cylinder radius="0.04" length="0.3"/>
      </geometry>
      <material name="light_gray">
        <color rgba="0.7 0.7 0.7 1.0"/>
      </material>
    </visual>
    <collision>
      <origin xyz="0 0 -0.15" rpy="1.57079632679 0 0"/>
      <geometry>
        <cylinder radius="0.04" length="0.3"/>
      </geometry>
    </collision>
    <inertial>
      <mass value="2.0"/>
      <origin xyz="0 0 -0.15" rpy="0 0 0"/>
      <inertia ixx="0.015" ixy="0" ixz="0" iyy="0.015" iyz="0" izz="0.001"/>
    </inertial>
  </link>

  <joint name="left_shoulder_pitch" type="revolute">
    <parent link="left_shoulder"/>
    <child link="left_upper_arm"/>
    <origin xyz="0 0 0"/>
    <axis xyz="0 1 0"/>
    <limit lower="-1.57" upper="1.57" effort="10.0" velocity="2.0"/>
    <dynamics damping="1.0" friction="0.1"/>
  </joint>

  <link name="left_lower_arm">
    <visual>
      <origin xyz="0 0 -0.15" rpy="1.57079632679 0 0"/>
      <geometry>
        <cylinder radius="0.03" length="0.3"/>
      </geometry>
      <material name="light_gray">
        <color rgba="0.7 0.7 0.7 1.0"/>
      </material>
    </visual>
    <collision>
      <origin xyz="0 0 -0.15" rpy="1.57079632679 0 0"/>
      <geometry>
        <cylinder radius="0.03" length="0.3"/>
      </geometry>
    </collision>
    <inertial>
      <mass value="1.5"/>
      <origin xyz="0 0 -0.15" rpy="0 0 0"/>
      <inertia ixx="0.01" ixy="0" ixz="0" iyy="0.01" iyz="0" izz="0.001"/>
    </inertial>
  </link>

  <joint name="left_elbow" type="revolute">
    <parent link="left_upper_arm"/>
    <child link="left_lower_arm"/>
    <origin xyz="0 0 -0.3"/>
    <axis xyz="0 1 0"/>
    <limit lower="-1.57" upper="1.57" effort="10.0" velocity="2.0"/>
    <dynamics damping="1.0" friction="0.1"/>
  </joint>

  <link name="left_hand">
    <visual>
      <origin xyz="0 0 -0.075" rpy="0 0 0"/>
      <geometry>
        <box size="0.12 0.08 0.15"/>
      </geometry>
      <material name="light_gray">
        <color rgba="0.7 0.7 0.7 1.0"/>
      </material>
    </visual>
    <collision>
      <origin xyz="0 0 -0.075" rpy="0 0 0"/>
      <geometry>
        <box size="0.12 0.08 0.15"/>
      </geometry>
    </collision>
    <inertial>
      <mass value="0.5"/>
      <origin xyz="0 0 -0.075" rpy="0 0 0"/>
      <inertia ixx="0.001" ixy="0" ixz="0" iyy="0.001" iyz="0" izz="0.001"/>
    </inertial>
  </link>

  <joint name="left_wrist" type="revolute">
    <parent link="left_lower_arm"/>
    <child link="left_hand"/>
    <origin xyz="0 0 -0.3"/>
    <axis xyz="0 0 1"/>
    <limit lower="-1.57" upper="1.57" effort="5.0" velocity="2.0"/>
    <dynamics damping="0.5" friction="0.1"/>
  </joint>

  <!-- Right Arm -->
  <link name="right_shoulder">
    <visual>
      <origin xyz="0.0 0 0" rpy="0 0 0"/>
      <geometry>
        <cylinder radius="0.06" length="0.12"/>
      </geometry>
      <material name="light_gray">
        <color rgba="0.7 0.7 0.7 1.0"/>
      </material>
    </visual>
    <collision>
      <origin xyz="0.0 0 0" rpy="0 0 0"/>
      <geometry>
        <cylinder radius="0.06" length="0.12"/>
      </geometry>
    </collision>
    <inertial>
      <mass value="1.0"/>
      <origin xyz="0 0 0" rpy="0 0 0"/>
      <inertia ixx="0.001" ixy="0" ixz="0" iyy="0.001" iyz="0" izz="0.002"/>
    </inertial>
  </link>

  <joint name="right_shoulder_yaw" type="revolute">
    <parent link="torso"/>
    <child link="right_shoulder"/>
    <origin xyz="-0.125 0.05 0.25"/>
    <axis xyz="0 0 1"/>
    <limit lower="-0.5" upper="1.57" effort="10.0" velocity="2.0"/>
    <dynamics damping="1.0" friction="0.1"/>
  </joint>

  <link name="right_upper_arm">
    <visual>
      <origin xyz="0 0 -0.15" rpy="1.57079632679 0 0"/>
      <geometry>
        <cylinder radius="0.04" length="0.3"/>
      </geometry>
      <material name="light_gray">
        <color rgba="0.7 0.7 0.7 1.0"/>
      </material>
    </visual>
    <collision>
      <origin xyz="0 0 -0.15" rpy="1.57079632679 0 0"/>
      <geometry>
        <cylinder radius="0.04" length="0.3"/>
      </geometry>
    </collision>
    <inertial>
      <mass value="2.0"/>
      <origin xyz="0 0 -0.15" rpy="0 0 0"/>
      <inertia ixx="0.015" ixy="0" ixz="0" iyy="0.015" iyz="0" izz="0.001"/>
    </inertial>
  </link>

  <joint name="right_shoulder_pitch" type="revolute">
    <parent link="right_shoulder"/>
    <child link="right_upper_arm"/>
    <origin xyz="0 0 0"/>
    <axis xyz="0 1 0"/>
    <limit lower="-1.57" upper="1.57" effort="10.0" velocity="2.0"/>
    <dynamics damping="1.0" friction="0.1"/>
  </joint>

  <link name="right_lower_arm">
    <visual>
      <origin xyz="0 0 -0.15" rpy="1.57079632679 0 0"/>
      <geometry>
        <cylinder radius="0.03" length="0.3"/>
      </geometry>
      <material name="light_gray">
        <color rgba="0.7 0.7 0.7 1.0"/>
      </material>
    </visual>
    <collision>
      <origin xyz="0 0 -0.15" rpy="1.57079632679 0 0"/>
      <geometry>
        <cylinder radius="0.03" length="0.3"/>
      </geometry>
    </collision>
    <inertial>
      <mass value="1.5"/>
      <origin xyz="0 0 -0.15" rpy="0 0 0"/>
      <inertia ixx="0.01" ixy="0" ixz="0" iyy="0.01" iyz="0" izz="0.001"/>
    </inertial>
  </link>

  <joint name="right_elbow" type="revolute">
    <parent link="right_upper_arm"/>
    <child link="right_lower_arm"/>
    <origin xyz="0 0 -0.3"/>
    <axis xyz="0 1 0"/>
    <limit lower="-1.57" upper="1.57" effort="10.0" velocity="2.0"/>
    <dynamics damping="1.0" friction="0.1"/>
  </joint>

  <link name="right_hand">
    <visual>
      <origin xyz="0 0 -0.075" rpy="0 0 0"/>
      <geometry>
        <box size="0.12 0.08 0.15"/>
      </geometry>
      <material name="light_gray">
        <color rgba="0.7 0.7 0.7 1.0"/>
      </material>
    </visual>
    <collision>
      <origin xyz="0 0 -0.075" rpy="0 0 0"/>
      <geometry>
        <box size="0.12 0.08 0.15"/>
      </geometry>
    </collision>
    <inertial>
      <mass value="0.5"/>
      <origin xyz="0 0 -0.075" rpy="0 0 0"/>
      <inertia ixx="0.001" ixy="0" ixz="0" iyy="0.001" iyz="0" izz="0.001"/>
    </inertial>
  </link>

  <joint name="right_wrist" type="revolute">
    <parent link="right_lower_arm"/>
    <child link="right_hand"/>
    <origin xyz="0 0 -0.3"/>
    <axis xyz="0 0 1"/>
    <limit lower="-1.57" upper="1.57" effort="5.0" velocity="2.0"/>
    <dynamics damping="0.5" friction="0.1"/>
  </joint>

  <!-- Left Leg -->
  <link name="left_hip">
    <visual>
      <origin xyz="0.0 0 0" rpy="0 0 0"/>
      <geometry>
        <cylinder radius="0.07" length="0.14"/>
      </geometry>
      <material name="light_gray">
        <color rgba="0.7 0.7 0.7 1.0"/>
      </material>
    </visual>
    <collision>
      <origin xyz="0.0 0 0" rpy="0 0 0"/>
      <geometry>
        <cylinder radius="0.07" length="0.14"/>
      </geometry>
    </collision>
    <inertial>
      <mass value="1.5"/>
      <origin xyz="0 0 0" rpy="0 0 0"/>
      <inertia ixx="0.003" ixy="0" ixz="0" iyy="0.003" iyz="0" izz="0.005"/>
    </inertial>
  </link>

  <joint name="left_hip_yaw" type="revolute">
    <parent link="pelvis"/>
    <child link="left_hip"/>
    <origin xyz="0.075 0.05 -0.075"/>
    <axis xyz="0 0 1"/>
    <limit lower="-0.5" upper="0.5" effort="20.0" velocity="1.0"/>
    <dynamics damping="2.0" friction="0.2"/>
  </joint>

  <link name="left_upper_leg">
    <visual>
      <origin xyz="0 0 -0.2" rpy="1.57079632679 0 0"/>
      <geometry>
        <cylinder radius="0.06" length="0.4"/>
      </geometry>
      <material name="light_gray">
        <color rgba="0.7 0.7 0.7 1.0"/>
      </material>
    </visual>
    <collision>
      <origin xyz="0 0 -0.2" rpy="1.57079632679 0 0"/>
      <geometry>
        <cylinder radius="0.06" length="0.4"/>
      </geometry>
    </collision>
    <inertial>
      <mass value="5.0"/>
      <origin xyz="0 0 -0.2" rpy="0 0 0"/>
      <inertia ixx="0.07" ixy="0" ixz="0" iyy="0.07" iyz="0" izz="0.01"/>
    </inertial>
  </link>

  <joint name="left_hip_pitch" type="revolute">
    <parent link="left_hip"/>
    <child link="left_upper_leg"/>
    <origin xyz="0 0 0"/>
    <axis xyz="0 1 0"/>
    <limit lower="-1.57" upper="0.5" effort="20.0" velocity="1.0"/>
    <dynamics damping="2.0" friction="0.2"/>
  </joint>

  <link name="left_lower_leg">
    <visual>
      <origin xyz="0 0 -0.2" rpy="1.57079632679 0 0"/>
      <geometry>
        <cylinder radius="0.05" length="0.4"/>
      </geometry>
      <material name="light_gray">
        <color rgba="0.7 0.7 0.7 1.0"/>
      </material>
    </visual>
    <collision>
      <origin xyz="0 0 -0.2" rpy="1.57079632679 0 0"/>
      <geometry>
        <cylinder radius="0.05" length="0.4"/>
      </geometry>
    </collision>
    <inertial>
      <mass value="3.0"/>
      <origin xyz="0 0 -0.2" rpy="0 0 0"/>
      <inertia ixx="0.04" ixy="0" ixz="0" iyy="0.04" iyz="0" izz="0.01"/>
    </inertial>
  </link>

  <joint name="left_knee" type="revolute">
    <parent link="left_upper_leg"/>
    <child link="left_lower_leg"/>
    <origin xyz="0 0 -0.4"/>
    <axis xyz="0 1 0"/>
    <limit lower="0" upper="1.57" effort="20.0" velocity="1.0"/>
    <dynamics damping="2.0" friction="0.2"/>
  </joint>

  <link name="left_foot">
    <visual>
      <origin xyz="0 0 -0.05" rpy="0 0 0"/>
      <geometry>
        <box size="0.18 0.08 0.1"/>
      </geometry>
      <material name="light_gray">
        <color rgba="0.7 0.7 0.7 1.0"/>
      </material>
    </visual>
    <collision>
      <origin xyz="0 0 -0.05" rpy="0 0 0"/>
      <geometry>
        <box size="0.18 0.08 0.1"/>
      </geometry>
    </collision>
    <inertial>
      <mass value="1.0"/>
      <origin xyz="0 0 -0.05" rpy="0 0 0"/>
      <inertia ixx="0.002" ixy="0" ixz="0" iyy="0.005" iyz="0" izz="0.005"/>
    </inertial>
  </link>

  <joint name="left_ankle" type="revolute">
    <parent link="left_lower_leg"/>
    <child link="left_foot"/>
    <origin xyz="0 0 -0.4"/>
    <axis xyz="0 0 1"/>
    <limit lower="-0.5" upper="0.5" effort="10.0" velocity="1.0"/>
    <dynamics damping="1.0" friction="0.1"/>
  </joint>

  <!-- Right Leg -->
  <link name="right_hip">
    <visual>
      <origin xyz="0.0 0 0" rpy="0 0 0"/>
      <geometry>
        <cylinder radius="0.07" length="0.14"/>
      </geometry>
      <material name="light_gray">
        <color rgba="0.7 0.7 0.7 1.0"/>
      </material>
    </visual>
    <collision>
      <origin xyz="0.0 0 0" rpy="0 0 0"/>
      <geometry>
        <cylinder radius="0.07" length="0.14"/>
      </geometry>
    </collision>
    <inertial>
      <mass value="1.5"/>
      <origin xyz="0 0 0" rpy="0 0 0"/>
      <inertia ixx="0.003" ixy="0" ixz="0" iyy="0.003" iyz="0" izz="0.005"/>
    </inertial>
  </link>

  <joint name="right_hip_yaw" type="revolute">
    <parent link="pelvis"/>
    <child link="right_hip"/>
    <origin xyz="-0.075 0.05 -0.075"/>
    <axis xyz="0 0 1"/>
    <limit lower="-0.5" upper="0.5" effort="20.0" velocity="1.0"/>
    <dynamics damping="2.0" friction="0.2"/>
  </joint>

  <link name="right_upper_leg">
    <visual>
      <origin xyz="0 0 -0.2" rpy="1.57079632679 0 0"/>
      <geometry>
        <cylinder radius="0.06" length="0.4"/>
      </geometry>
      <material name="light_gray">
        <color rgba="0.7 0.7 0.7 1.0"/>
      </material>
    </visual>
    <collision>
      <origin xyz="0 0 -0.2" rpy="1.57079632679 0 0"/>
      <geometry>
        <cylinder radius="0.06" length="0.4"/>
      </geometry>
    </collision>
    <inertial>
      <mass value="5.0"/>
      <origin xyz="0 0 -0.2" rpy="0 0 0"/>
      <inertia ixx="0.07" ixy="0" ixz="0" iyy="0.07" iyz="0" izz="0.01"/>
    </inertial>
  </link>

  <joint name="right_hip_pitch" type="revolute">
    <parent link="right_hip"/>
    <child link="right_upper_leg"/>
    <origin xyz="0 0 0"/>
    <axis xyz="0 1 0"/>
    <limit lower="-1.57" upper="0.5" effort="20.0" velocity="1.0"/>
    <dynamics damping="2.0" friction="0.2"/>
  </joint>

  <link name="right_lower_leg">
    <visual>
      <origin xyz="0 0 -0.2" rpy="1.57079632679 0 0"/>
      <geometry>
        <cylinder radius="0.05" length="0.4"/>
      </geometry>
      <material name="light_gray">
        <color rgba="0.7 0.7 0.7 1.0"/>
      </material>
    </visual>
    <collision>
      <origin xyz="0 0 -0.2" rpy="1.57079632679 0 0"/>
      <geometry>
        <cylinder radius="0.05" length="0.4"/>
      </geometry>
    </collision>
    <inertial>
      <mass value="3.0"/>
      <origin xyz="0 0 -0.2" rpy="0 0 0"/>
      <inertia ixx="0.04" ixy="0" ixz="0" iyy="0.04" iyz="0" izz="0.01"/>
    </inertial>
  </link>

  <joint name="right_knee" type="revolute">
    <parent link="right_upper_leg"/>
    <child link="right_lower_leg"/>
    <origin xyz="0 0 -0.4"/>
    <axis xyz="0 1 0"/>
    <limit lower="0" upper="1.57" effort="20.0" velocity="1.0"/>
    <dynamics damping="2.0" friction="0.2"/>
  </joint>

  <link name="right_foot">
    <visual>
      <origin xyz="0 0 -0.05" rpy="0 0 0"/>
      <geometry>
        <box size="0.18 0.08 0.1"/>
      </geometry>
      <material name="light_gray">
        <color rgba="0.7 0.7 0.7 1.0"/>
      </material>
    </visual>
    <collision>
      <origin xyz="0 0 -0.05" rpy="0 0 0"/>
      <geometry>
        <box size="0.18 0.08 0.1"/>
      </geometry>
    </collision>
    <inertial>
      <mass value="1.0"/>
      <origin xyz="0 0 -0.05" rpy="0 0 0"/>
      <inertia ixx="0.002" ixy="0" ixz="0" iyy="0.005" iyz="0" izz="0.005"/>
    </inertial>
  </link>

  <joint name="right_ankle" type="revolute">
    <parent link="right_lower_leg"/>
    <child link="right_foot"/>
    <origin xyz="0 0 -0.4"/>
    <axis xyz="0 0 1"/>
    <limit lower="-0.5" upper="0.5" effort="10.0" velocity="1.0"/>
    <dynamics damping="1.0" friction="0.1"/>
  </joint>

  <!-- Gazebo-specific elements for simulation -->
  <gazebo reference="pelvis">
    <material>Gazebo/Grey</material>
  </gazebo>

  <gazebo reference="torso">
    <material>Gazebo/LightGrey</material>
  </gazebo>

  <gazebo reference="head">
    <material>Gazebo/Skin</material>
  </gazebo>

  <gazebo>
    <plugin name="humanoid_controller" filename="libgazebo_ros_control.so">
      <robotNamespace>/humanoid</robotNamespace>
    </plugin>
  </gazebo>
</robot>