<?xml version="1.0"?>
<robot name="humanoid_skeleton">
  <!-- Base/Pelvis link -->
  <link name="base_link">
    <visual>
      <geometry>
        <box size="0.3 0.2 0.4"/>
      </geometry>
      <material name="light_gray">
        <color rgba="0.7 0.7 0.7 1.0"/>
      </material>
    </visual>
    <collision>
      <geometry>
        <box size="0.3 0.2 0.4"/>
      </geometry>
    </collision>
    <inertial>
      <mass value="10.0"/>
      <inertia ixx="0.2" ixy="0.0" ixz="0.0" iyy="0.3" iyz="0.0" izz="0.2"/>
    </inertial>
  </link>

  <!-- Torso -->
  <link name="torso">
    <visual>
      <geometry>
        <box size="0.3 0.2 0.6"/>
      </geometry>
      <material name="light_gray">
        <color rgba="0.7 0.7 0.7 1.0"/>
      </material>
    </visual>
    <collision>
      <geometry>
        <box size="0.3 0.2 0.6"/>
      </geometry>
    </collision>
    <inertial>
      <mass value="8.0"/>
      <inertia ixx="0.3" ixy="0.0" ixz="0.0" iyy="0.4" iyz="0.0" izz="0.3"/>
    </inertial>
  </link>

  <joint name="torso_joint" type="fixed">
    <parent link="base_link"/>
    <child link="torso"/>
    <origin xyz="0 0 0.3"/>
  </joint>

  <!-- Head -->
  <link name="head">
    <visual>
      <geometry>
        <sphere radius="0.1"/>
      </geometry>
      <material name="skin">
        <color rgba="1.0 0.8 0.6 1.0"/>
      </material>
    </visual>
    <collision>
      <geometry>
        <sphere radius="0.1"/>
      </geometry>
    </collision>
    <inertial>
      <mass value="2.0"/>
      <inertia ixx="0.02" ixy="0.0" ixz="0.0" iyy="0.02" iyz="0.0" izz="0.02"/>
    </inertial>
  </link>

  <joint name="neck_joint" type="revolute">
    <parent link="torso"/>
    <child link="head"/>
    <origin xyz="0 0 0.4"/>
    <axis xyz="0 1 0"/>
    <limit lower="-0.5" upper="0.5" effort="10.0" velocity="2.0"/>
  </joint>

  <!-- Left Arm -->
  <link name="left_shoulder">
    <visual>
      <geometry>
        <cylinder radius="0.05" length="0.2"/>
      </geometry>
      <material name="light_gray">
        <color rgba="0.7 0.7 0.7 1.0"/>
      </material>
    </visual>
    <collision>
      <geometry>
        <cylinder radius="0.05" length="0.2"/>
      </geometry>
    </collision>
    <inertial>
      <mass value="1.0"/>
      <inertia ixx="0.005" ixy="0.0" ixz="0.0" iyy="0.005" iyz="0.0" izz="0.001"/>
    </inertial>
  </link>

  <joint name="left_shoulder_joint" type="revolute">
    <parent link="torso"/>
    <child link="left_shoulder"/>
    <origin xyz="0.2 0 0.2" rpy="0 0 -1.57"/>
    <axis xyz="0 0 1"/>
    <limit lower="-1.57" upper="1.57" effort="10.0" velocity="2.0"/>
  </joint>

  <link name="left_upper_arm">
    <visual>
      <geometry>
        <cylinder radius="0.04" length="0.3"/>
      </geometry>
      <material name="light_gray">
        <color rgba="0.7 0.7 0.7 1.0"/>
      </material>
    </visual>
    <collision>
      <geometry>
        <cylinder radius="0.04" length="0.3"/>
      </geometry>
    </collision>
    <inertial>
      <mass value="1.5"/>
      <inertia ixx="0.01" ixy="0.0" ixz="0.0" iyy="0.01" iyz="0.0" izz="0.001"/>
    </inertial>
  </link>

  <joint name="left_elbow_joint" type="revolute">
    <parent link="left_shoulder"/>
    <child link="left_upper_arm"/>
    <origin xyz="0 0 -0.15"/>
    <axis xyz="0 1 0"/>
    <limit lower="-1.57" upper="1.57" effort="10.0" velocity="2.0"/>
  </joint>

  <link name="left_lower_arm">
    <visual>
      <geometry>
        <cylinder radius="0.03" length="0.3"/>
      </geometry>
      <material name="light_gray">
        <color rgba="0.7 0.7 0.7 1.0"/>
      </material>
    </visual>
    <collision>
      <geometry>
        <cylinder radius="0.03" length="0.3"/>
      </geometry>
    </collision>
    <inertial>
      <mass value="1.0"/>
      <inertia ixx="0.008" ixy="0.0" ixz="0.0" iyy="0.008" iyz="0.0" izz="0.001"/>
    </inertial>
  </link>

  <joint name="left_wrist_joint" type="revolute">
    <parent link="left_upper_arm"/>
    <child link="left_lower_arm"/>
    <origin xyz="0 0 -0.15"/>
    <axis xyz="0 0 1"/>
    <limit lower="-1.57" upper="1.57" effort="5.0" velocity="2.0"/>
  </joint>

  <!-- Right Arm (mirror of left) -->
  <link name="right_shoulder">
    <visual>
      <geometry>
        <cylinder radius="0.05" length="0.2"/>
      </geometry>
      <material name="light_gray">
        <color rgba="0.7 0.7 0.7 1.0"/>
      </material>
    </visual>
    <collision>
      <geometry>
        <cylinder radius="0.05" length="0.2"/>
      </geometry>
    </collision>
    <inertial>
      <mass value="1.0"/>
      <inertia ixx="0.005" ixy="0.0" ixz="0.0" iyy="0.005" iyz="0.0" izz="0.001"/>
    </inertial>
  </link>

  <joint name="right_shoulder_joint" type="revolute">
    <parent link="torso"/>
    <child link="right_shoulder"/>
    <origin xyz="-0.2 0 0.2" rpy="0 0 1.57"/>
    <axis xyz="0 0 1"/>
    <limit lower="-1.57" upper="1.57" effort="10.0" velocity="2.0"/>
  </joint>

  <link name="right_upper_arm">
    <visual>
      <geometry>
        <cylinder radius="0.04" length="0.3"/>
      </geometry>
      <material name="light_gray">
        <color rgba="0.7 0.7 0.7 1.0"/>
      </material>
    </visual>
    <collision>
      <geometry>
        <cylinder radius="0.04" length="0.3"/>
      </geometry>
    </collision>
    <inertial>
      <mass value="1.5"/>
      <inertia ixx="0.01" ixy="0.0" ixz="0.0" iyy="0.01" iyz="0.0" izz="0.001"/>
    </inertial>
  </link>

  <joint name="right_elbow_joint" type="revolute">
    <parent link="right_shoulder"/>
    <child link="right_upper_arm"/>
    <origin xyz="0 0 -0.15"/>
    <axis xyz="0 1 0"/>
    <limit lower="-1.57" upper="1.57" effort="10.0" velocity="2.0"/>
  </joint>

  <link name="right_lower_arm">
    <visual>
      <geometry>
        <cylinder radius="0.03" length="0.3"/>
      </geometry>
      <material name="light_gray">
        <color rgba="0.7 0.7 0.7 1.0"/>
      </material>
    </visual>
    <collision>
      <geometry>
        <cylinder radius="0.03" length="0.3"/>
      </geometry>
    </collision>
    <inertial>
      <mass value="1.0"/>
      <inertia ixx="0.008" ixy="0.0" ixz="0.0" iyy="0.008" iyz="0.0" izz="0.001"/>
    </inertial>
  </link>

  <joint name="right_wrist_joint" type="revolute">
    <parent link="right_upper_arm"/>
    <child link="right_lower_arm"/>
    <origin xyz="0 0 -0.15"/>
    <axis xyz="0 0 1"/>
    <limit lower="-1.57" upper="1.57" effort="5.0" velocity="2.0"/>
  </joint>

  <!-- Left Leg -->
  <link name="left_hip">
    <visual>
      <geometry>
        <cylinder radius="0.06" length="0.15"/>
      </geometry>
      <material name="light_gray">
        <color rgba="0.7 0.7 0.7 1.0"/>
      </material>
    </visual>
    <collision>
      <geometry>
        <cylinder radius="0.06" length="0.15"/>
      </geometry>
    </collision>
    <inertial>
      <mass value="1.5"/>
      <inertia ixx="0.008" ixy="0.0" ixz="0.0" iyy="0.008" iyz="0.0" izz="0.002"/>
    </inertial>
  </link>

  <joint name="left_hip_joint" type="revolute">
    <parent link="base_link"/>
    <child link="left_hip"/>
    <origin xyz="0.1 0 -0.2" rpy="0 0 0"/>
    <axis xyz="0 0 1"/>
    <limit lower="-0.5" upper="0.5" effort="20.0" velocity="2.0"/>
  </joint>

  <link name="left_upper_leg">
    <visual>
      <geometry>
        <cylinder radius="0.05" length="0.4"/>
      </geometry>
      <material name="light_gray">
        <color rgba="0.7 0.7 0.7 1.0"/>
      </material>
    </visual>
    <collision>
      <geometry>
        <cylinder radius="0.05" length="0.4"/>
      </geometry>
    </collision>
    <inertial>
      <mass value="3.0"/>
      <inertia ixx="0.04" ixy="0.0" ixz="0.0" iyy="0.04" iyz="0.0" izz="0.002"/>
    </inertial>
  </link>

  <joint name="left_knee_joint" type="revolute">
    <parent link="left_hip"/>
    <child link="left_upper_leg"/>
    <origin xyz="0 0 -0.2"/>
    <axis xyz="0 1 0"/>
    <limit lower="0" upper="1.57" effort="20.0" velocity="2.0"/>
  </joint>

  <link name="left_lower_leg">
    <visual>
      <geometry>
        <cylinder radius="0.04" length="0.4"/>
      </geometry>
      <material name="light_gray">
        <color rgba="0.7 0.7 0.7 1.0"/>
      </material>
    </visual>
    <collision>
      <geometry>
        <cylinder radius="0.04" length="0.4"/>
      </geometry>
    </collision>
    <inertial>
      <mass value="2.0"/>
      <inertia ixx="0.03" ixy="0.0" ixz="0.0" iyy="0.03" iyz="0.0" izz="0.001"/>
    </inertial>
  </link>

  <joint name="left_ankle_joint" type="revolute">
    <parent link="left_upper_leg"/>
    <child link="left_lower_leg"/>
    <origin xyz="0 0 -0.2"/>
    <axis xyz="0 0 1"/>
    <limit lower="-0.5" upper="0.5" effort="10.0" velocity="2.0"/>
  </joint>

  <!-- Right Leg (mirror of left) -->
  <link name="right_hip">
    <visual>
      <geometry>
        <cylinder radius="0.06" length="0.15"/>
      </geometry>
      <material name="light_gray">
        <color rgba="0.7 0.7 0.7 1.0"/>
      </material>
    </visual>
    <collision>
      <geometry>
        <cylinder radius="0.06" length="0.15"/>
      </geometry>
    </collision>
    <inertial>
      <mass value="1.5"/>
      <inertia ixx="0.008" ixy="0.0" ixz="0.0" iyy="0.008" iyz="0.0" izz="0.002"/>
    </inertial>
  </link>

  <joint name="right_hip_joint" type="revolute">
    <parent link="base_link"/>
    <child link="right_hip"/>
    <origin xyz="-0.1 0 -0.2" rpy="0 0 0"/>
    <axis xyz="0 0 1"/>
    <limit lower="-0.5" upper="0.5" effort="20.0" velocity="2.0"/>
  </joint>

  <link name="right_upper_leg">
    <visual>
      <geometry>
        <cylinder radius="0.05" length="0.4"/>
      </geometry>
      <material name="light_gray">
        <color rgba="0.7 0.7 0.7 1.0"/>
      </material>
    </visual>
    <collision>
      <geometry>
        <cylinder radius="0.05" length="0.4"/>
      </geometry>
    </collision>
    <inertial>
      <mass value="3.0"/>
      <inertia ixx="0.04" ixy="0.0" ixz="0.0" iyy="0.04" iyz="0.0" izz="0.002"/>
    </inertial>
  </link>

  <joint name="right_knee_joint" type="revolute">
    <parent link="right_hip"/>
    <child link="right_upper_leg"/>
    <origin xyz="0 0 -0.2"/>
    <axis xyz="0 1 0"/>
    <limit lower="0" upper="1.57" effort="20.0" velocity="2.0"/>
  </joint>

  <link name="right_lower_leg">
    <visual>
      <geometry>
        <cylinder radius="0.04" length="0.4"/>
      </geometry>
      <material name="light_gray">
        <color rgba="0.7 0.7 0.7 1.0"/>
      </material>
    </visual>
    <collision>
      <geometry>
        <cylinder radius="0.04" length="0.4"/>
      </geometry>
    </collision>
    <inertial>
      <mass value="2.0"/>
      <inertia ixx="0.03" ixy="0.0" ixz="0.0" iyy="0.03" iyz="0.0" izz="0.001"/>
    </inertial>
  </link>

  <joint name="right_ankle_joint" type="revolute">
    <parent link="right_upper_leg"/>
    <child link="right_lower_leg"/>
    <origin xyz="0 0 -0.2"/>
    <axis xyz="0 0 1"/>
    <limit lower="-0.5" upper="0.5" effort="10.0" velocity="2.0"/>
  </joint>
</robot>